[2025-07-09T05:10:22.271+0000] {local_task_job_runner.py:120} INFO - ::group::Pre task execution logs
[2025-07-09T05:10:22.374+0000] {taskinstance.py:2076} INFO - Dependencies all met for dep_context=non-requeueable deps ti=<TaskInstance: bash_call_python_file.load_task manual__2025-07-09T05:03:18.296639+00:00 [queued]>
[2025-07-09T05:10:22.399+0000] {taskinstance.py:2076} INFO - Dependencies all met for dep_context=requeueable deps ti=<TaskInstance: bash_call_python_file.load_task manual__2025-07-09T05:03:18.296639+00:00 [queued]>
[2025-07-09T05:10:22.400+0000] {taskinstance.py:2306} INFO - Starting attempt 4 of 4
[2025-07-09T05:10:22.472+0000] {taskinstance.py:2330} INFO - Executing <Task(PythonOperator): load_task> on 2025-07-09 05:03:18.296639+00:00
[2025-07-09T05:10:22.487+0000] {standard_task_runner.py:90} INFO - Running: ['airflow', 'tasks', 'run', 'bash_call_python_file', 'load_task', 'manual__2025-07-09T05:03:18.296639+00:00', '--job-id', '38', '--raw', '--subdir', 'DAGS_FOLDER/test_dag.py', '--cfg-path', '/tmp/tmpla120xo7']
[2025-07-09T05:10:22.495+0000] {logging_mixin.py:188} WARNING - /home/airflow/.local/lib/python3.12/site-packages/airflow/task/task_runner/standard_task_runner.py:61 DeprecationWarning: This process (pid=286) is multi-threaded, use of fork() may lead to deadlocks in the child.
[2025-07-09T05:10:22.496+0000] {standard_task_runner.py:91} INFO - Job 38: Subtask load_task
[2025-07-09T05:10:22.496+0000] {standard_task_runner.py:63} INFO - Started process 287 to run task
[2025-07-09T05:10:22.662+0000] {task_command.py:426} INFO - Running <TaskInstance: bash_call_python_file.load_task manual__2025-07-09T05:03:18.296639+00:00 [running]> on host fe3fd911cec1
[2025-07-09T05:10:22.903+0000] {taskinstance.py:2648} INFO - Exporting env vars: AIRFLOW_CTX_DAG_OWNER='airflow' AIRFLOW_CTX_DAG_ID='bash_call_python_file' AIRFLOW_CTX_TASK_ID='load_task' AIRFLOW_CTX_EXECUTION_DATE='2025-07-09T05:03:18.296639+00:00' AIRFLOW_CTX_TRY_NUMBER='4' AIRFLOW_CTX_DAG_RUN_ID='manual__2025-07-09T05:03:18.296639+00:00'
[2025-07-09T05:10:22.904+0000] {taskinstance.py:430} INFO - ::endgroup::
[2025-07-09T05:10:23.094+0000] {logging_mixin.py:188} INFO - ‚ùå Error inserting data into MySQL: 1062 (23000): Duplicate entry '1' for key 'users.PRIMARY'
[2025-07-09T05:10:23.096+0000] {taskinstance.py:441} INFO - ::group::Post task execution logs
[2025-07-09T05:10:23.102+0000] {taskinstance.py:2905} ERROR - Task failed with exception
Traceback (most recent call last):
  File "/home/airflow/.local/lib/python3.12/site-packages/mysql/connector/connection_cext.py", line 697, in cmd_query
    self._cmysql.query(
_mysql_connector.MySQLInterfaceError: Duplicate entry '1' for key 'users.PRIMARY'

The above exception was the direct cause of the following exception:

Traceback (most recent call last):
  File "/home/airflow/.local/lib/python3.12/site-packages/airflow/models/taskinstance.py", line 465, in _execute_task
    result = _execute_callable(context=context, **execute_callable_kwargs)
             ^^^^^^^^^^^^^^^^^^^^^^^^^^^^^^^^^^^^^^^^^^^^^^^^^^^^^^^^^^^^^
  File "/home/airflow/.local/lib/python3.12/site-packages/airflow/models/taskinstance.py", line 432, in _execute_callable
    return execute_callable(context=context, **execute_callable_kwargs)
           ^^^^^^^^^^^^^^^^^^^^^^^^^^^^^^^^^^^^^^^^^^^^^^^^^^^^^^^^^^^^
  File "/home/airflow/.local/lib/python3.12/site-packages/airflow/models/baseoperator.py", line 401, in wrapper
    return func(self, *args, **kwargs)
           ^^^^^^^^^^^^^^^^^^^^^^^^^^^
  File "/home/airflow/.local/lib/python3.12/site-packages/airflow/operators/python.py", line 235, in execute
    return_value = self.execute_callable()
                   ^^^^^^^^^^^^^^^^^^^^^^^
  File "/home/airflow/.local/lib/python3.12/site-packages/airflow/operators/python.py", line 252, in execute_callable
    return self.python_callable(*self.op_args, **self.op_kwargs)
           ^^^^^^^^^^^^^^^^^^^^^^^^^^^^^^^^^^^^^^^^^^^^^^^^^^^^^
  File "/opt/airflow/dags/test_dag.py", line 27, in load_task
    load_data(data)
  File "/opt/airflow/ETL/load/load_to_mysql.py", line 18, in load_data
    cursor.execute("""
  File "/home/airflow/.local/lib/python3.12/site-packages/mysql/connector/cursor_cext.py", line 372, in execute
    result = self._cnx.cmd_query(
             ^^^^^^^^^^^^^^^^^^^^
  File "/home/airflow/.local/lib/python3.12/site-packages/mysql/connector/opentelemetry/context_propagation.py", line 111, in wrapper
    result = method(cnx, *args, **kwargs)
             ^^^^^^^^^^^^^^^^^^^^^^^^^^^^
  File "/home/airflow/.local/lib/python3.12/site-packages/mysql/connector/connection_cext.py", line 705, in cmd_query
    raise get_mysql_exception(
mysql.connector.errors.IntegrityError: 1062 (23000): Duplicate entry '1' for key 'users.PRIMARY'
[2025-07-09T05:10:23.188+0000] {taskinstance.py:1206} INFO - Marking task as FAILED. dag_id=bash_call_python_file, task_id=load_task, run_id=manual__2025-07-09T05:03:18.296639+00:00, execution_date=20250709T050318, start_date=20250709T051022, end_date=20250709T051023
[2025-07-09T05:10:23.235+0000] {standard_task_runner.py:110} ERROR - Failed to execute job 38 for task load_task (1062 (23000): Duplicate entry '1' for key 'users.PRIMARY'; 287)
[2025-07-09T05:10:23.280+0000] {local_task_job_runner.py:240} INFO - Task exited with return code 1
[2025-07-09T05:10:23.318+0000] {taskinstance.py:3503} INFO - 0 downstream tasks scheduled from follow-on schedule check
[2025-07-09T05:10:23.323+0000] {local_task_job_runner.py:222} INFO - ::endgroup::
